[15Mar 11:53:52] INFO [news.views:14] NewsList.get_queryset called
[15Mar 12:05:44] INFO [news.views:15] NewsList.get_queryset called
[15Mar 12:16:32] INFO [news.views:16] NewsList.get_queryset called
[15Mar 12:16:33] ERROR [django.request:228] Internal Server Error: /news/
Traceback (most recent call last):
  File "/home/kotbegemot/Документы/d10/venv/lib/python3.6/site-packages/django/core/handlers/exception.py", line 34, in inner
    response = get_response(request)
  File "/home/kotbegemot/Документы/d10/venv/lib/python3.6/site-packages/django/core/handlers/base.py", line 115, in _get_response
    response = self.process_exception_by_middleware(e, request)
  File "/home/kotbegemot/Документы/d10/venv/lib/python3.6/site-packages/django/core/handlers/base.py", line 113, in _get_response
    response = wrapped_callback(request, *callback_args, **callback_kwargs)
  File "/home/kotbegemot/Документы/d10/venv/lib/python3.6/site-packages/django/views/generic/base.py", line 71, in view
    return self.dispatch(request, *args, **kwargs)
  File "/home/kotbegemot/Документы/d10/venv/lib/python3.6/site-packages/django/views/generic/base.py", line 97, in dispatch
    return handler(request, *args, **kwargs)
  File "/home/kotbegemot/Документы/d10/venv/lib/python3.6/site-packages/django/views/generic/list.py", line 142, in get
    self.object_list = self.get_queryset()
  File "/home/kotbegemot/Документы/d10/deb_test/news/views.py", line 24, in get_queryset
    import q; q(news); q(news[0])
ModuleNotFoundError: No module named 'q'
[15Mar 12:17:48] INFO [news.views:16] NewsList.get_queryset called
[15Mar 12:17:49] ERROR [django.request:228] Internal Server Error: /news/
Traceback (most recent call last):
  File "/home/kotbegemot/Документы/d10/venv/lib/python3.6/site-packages/django/core/handlers/exception.py", line 34, in inner
    response = get_response(request)
  File "/home/kotbegemot/Документы/d10/venv/lib/python3.6/site-packages/django/core/handlers/base.py", line 115, in _get_response
    response = self.process_exception_by_middleware(e, request)
  File "/home/kotbegemot/Документы/d10/venv/lib/python3.6/site-packages/django/core/handlers/base.py", line 113, in _get_response
    response = wrapped_callback(request, *callback_args, **callback_kwargs)
  File "/home/kotbegemot/Документы/d10/venv/lib/python3.6/site-packages/django/views/generic/base.py", line 71, in view
    return self.dispatch(request, *args, **kwargs)
  File "/home/kotbegemot/Документы/d10/venv/lib/python3.6/site-packages/django/views/generic/base.py", line 97, in dispatch
    return handler(request, *args, **kwargs)
  File "/home/kotbegemot/Документы/d10/venv/lib/python3.6/site-packages/django/views/generic/list.py", line 142, in get
    self.object_list = self.get_queryset()
  File "/home/kotbegemot/Документы/d10/deb_test/news/views.py", line 24, in get_queryset
    import q; q(news); q(news[0])
ModuleNotFoundError: No module named 'q'
[15Mar 12:19:05] INFO [news.views:16] NewsList.get_queryset called
[19Mar 10:48:49] WARNING [django.request:228] Not Found: /
[19Mar 10:48:49] WARNING [django.request:228] Not Found: /favicon.ico
[19Mar 10:48:53] WARNING [django.request:228] Not Found: /cars
[19Mar 10:49:30] ERROR [django.request:228] Internal Server Error: /cars/
Traceback (most recent call last):
  File "/home/kotbegemot/Документы/d10/venv/lib/python3.6/site-packages/django/core/handlers/exception.py", line 34, in inner
    response = get_response(request)
  File "/home/kotbegemot/Документы/d10/venv/lib/python3.6/site-packages/django/core/handlers/base.py", line 145, in _get_response
    response = self.process_exception_by_middleware(e, request)
  File "/home/kotbegemot/Документы/d10/venv/lib/python3.6/site-packages/django/core/handlers/base.py", line 143, in _get_response
    response = response.render()
  File "/home/kotbegemot/Документы/d10/venv/lib/python3.6/site-packages/django/template/response.py", line 105, in render
    self.content = self.rendered_content
  File "/home/kotbegemot/Документы/d10/venv/lib/python3.6/site-packages/django/template/response.py", line 81, in rendered_content
    template = self.resolve_template(self.template_name)
  File "/home/kotbegemot/Документы/d10/venv/lib/python3.6/site-packages/django/template/response.py", line 63, in resolve_template
    return select_template(template, using=self.using)
  File "/home/kotbegemot/Документы/d10/venv/lib/python3.6/site-packages/django/template/loader.py", line 47, in select_template
    raise TemplateDoesNotExist(', '.join(template_name_list), chain=chain)
django.template.exceptions.TemplateDoesNotExist: core/index.html
[19Mar 10:49:49] ERROR [django.request:228] Internal Server Error: /cars/
Traceback (most recent call last):
  File "/home/kotbegemot/Документы/d10/venv/lib/python3.6/site-packages/django/core/handlers/exception.py", line 34, in inner
    response = get_response(request)
  File "/home/kotbegemot/Документы/d10/venv/lib/python3.6/site-packages/django/core/handlers/base.py", line 145, in _get_response
    response = self.process_exception_by_middleware(e, request)
  File "/home/kotbegemot/Документы/d10/venv/lib/python3.6/site-packages/django/core/handlers/base.py", line 143, in _get_response
    response = response.render()
  File "/home/kotbegemot/Документы/d10/venv/lib/python3.6/site-packages/django/template/response.py", line 105, in render
    self.content = self.rendered_content
  File "/home/kotbegemot/Документы/d10/venv/lib/python3.6/site-packages/django/template/response.py", line 83, in rendered_content
    return template.render(context, self._request)
  File "/home/kotbegemot/Документы/d10/venv/lib/python3.6/site-packages/django/template/backends/django.py", line 61, in render
    return self.template.render(context)
  File "/home/kotbegemot/Документы/d10/venv/lib/python3.6/site-packages/django/template/base.py", line 171, in render
    return self._render(context)
  File "/home/kotbegemot/Документы/d10/venv/lib/python3.6/site-packages/django/test/utils.py", line 95, in instrumented_test_render
    return self.nodelist.render(context)
  File "/home/kotbegemot/Документы/d10/venv/lib/python3.6/site-packages/django/template/base.py", line 936, in render
    bit = node.render_annotated(context)
  File "/home/kotbegemot/Документы/d10/venv/lib/python3.6/site-packages/django/template/base.py", line 903, in render_annotated
    return self.render(context)
  File "/home/kotbegemot/Документы/d10/venv/lib/python3.6/site-packages/django/template/defaulttags.py", line 443, in render
    url = reverse(view_name, args=args, kwargs=kwargs, current_app=current_app)
  File "/home/kotbegemot/Документы/d10/venv/lib/python3.6/site-packages/django/urls/base.py", line 87, in reverse
    return iri_to_uri(resolver._reverse_with_prefix(view, prefix, *args, **kwargs))
  File "/home/kotbegemot/Документы/d10/venv/lib/python3.6/site-packages/django/urls/resolvers.py", line 677, in _reverse_with_prefix
    raise NoReverseMatch(msg)
django.urls.exceptions.NoReverseMatch: Reverse for 'main' not found. 'main' is not a valid view function or pattern name.
[19Mar 10:50:46] ERROR [django.request:228] Internal Server Error: /cars/
Traceback (most recent call last):
  File "/home/kotbegemot/Документы/d10/venv/lib/python3.6/site-packages/django/core/handlers/exception.py", line 34, in inner
    response = get_response(request)
  File "/home/kotbegemot/Документы/d10/venv/lib/python3.6/site-packages/django/core/handlers/base.py", line 145, in _get_response
    response = self.process_exception_by_middleware(e, request)
  File "/home/kotbegemot/Документы/d10/venv/lib/python3.6/site-packages/django/core/handlers/base.py", line 143, in _get_response
    response = response.render()
  File "/home/kotbegemot/Документы/d10/venv/lib/python3.6/site-packages/django/template/response.py", line 105, in render
    self.content = self.rendered_content
  File "/home/kotbegemot/Документы/d10/venv/lib/python3.6/site-packages/django/template/response.py", line 83, in rendered_content
    return template.render(context, self._request)
  File "/home/kotbegemot/Документы/d10/venv/lib/python3.6/site-packages/django/template/backends/django.py", line 61, in render
    return self.template.render(context)
  File "/home/kotbegemot/Документы/d10/venv/lib/python3.6/site-packages/django/template/base.py", line 171, in render
    return self._render(context)
  File "/home/kotbegemot/Документы/d10/venv/lib/python3.6/site-packages/django/test/utils.py", line 95, in instrumented_test_render
    return self.nodelist.render(context)
  File "/home/kotbegemot/Документы/d10/venv/lib/python3.6/site-packages/django/template/base.py", line 936, in render
    bit = node.render_annotated(context)
  File "/home/kotbegemot/Документы/d10/venv/lib/python3.6/site-packages/django/template/base.py", line 903, in render_annotated
    return self.render(context)
  File "/home/kotbegemot/Документы/d10/venv/lib/python3.6/site-packages/django/template/defaulttags.py", line 443, in render
    url = reverse(view_name, args=args, kwargs=kwargs, current_app=current_app)
  File "/home/kotbegemot/Документы/d10/venv/lib/python3.6/site-packages/django/urls/base.py", line 87, in reverse
    return iri_to_uri(resolver._reverse_with_prefix(view, prefix, *args, **kwargs))
  File "/home/kotbegemot/Документы/d10/venv/lib/python3.6/site-packages/django/urls/resolvers.py", line 677, in _reverse_with_prefix
    raise NoReverseMatch(msg)
django.urls.exceptions.NoReverseMatch: Reverse for 'cars/index.html' not found. 'cars/index.html' is not a valid view function or pattern name.
[19Mar 10:50:58] ERROR [django.request:228] Internal Server Error: /cars/
Traceback (most recent call last):
  File "/home/kotbegemot/Документы/d10/venv/lib/python3.6/site-packages/django/core/handlers/exception.py", line 34, in inner
    response = get_response(request)
  File "/home/kotbegemot/Документы/d10/venv/lib/python3.6/site-packages/django/core/handlers/base.py", line 145, in _get_response
    response = self.process_exception_by_middleware(e, request)
  File "/home/kotbegemot/Документы/d10/venv/lib/python3.6/site-packages/django/core/handlers/base.py", line 143, in _get_response
    response = response.render()
  File "/home/kotbegemot/Документы/d10/venv/lib/python3.6/site-packages/django/template/response.py", line 105, in render
    self.content = self.rendered_content
  File "/home/kotbegemot/Документы/d10/venv/lib/python3.6/site-packages/django/template/response.py", line 83, in rendered_content
    return template.render(context, self._request)
  File "/home/kotbegemot/Документы/d10/venv/lib/python3.6/site-packages/django/template/backends/django.py", line 61, in render
    return self.template.render(context)
  File "/home/kotbegemot/Документы/d10/venv/lib/python3.6/site-packages/django/template/base.py", line 171, in render
    return self._render(context)
  File "/home/kotbegemot/Документы/d10/venv/lib/python3.6/site-packages/django/test/utils.py", line 95, in instrumented_test_render
    return self.nodelist.render(context)
  File "/home/kotbegemot/Документы/d10/venv/lib/python3.6/site-packages/django/template/base.py", line 936, in render
    bit = node.render_annotated(context)
  File "/home/kotbegemot/Документы/d10/venv/lib/python3.6/site-packages/django/template/base.py", line 903, in render_annotated
    return self.render(context)
  File "/home/kotbegemot/Документы/d10/venv/lib/python3.6/site-packages/django/template/defaulttags.py", line 443, in render
    url = reverse(view_name, args=args, kwargs=kwargs, current_app=current_app)
  File "/home/kotbegemot/Документы/d10/venv/lib/python3.6/site-packages/django/urls/base.py", line 87, in reverse
    return iri_to_uri(resolver._reverse_with_prefix(view, prefix, *args, **kwargs))
  File "/home/kotbegemot/Документы/d10/venv/lib/python3.6/site-packages/django/urls/resolvers.py", line 677, in _reverse_with_prefix
    raise NoReverseMatch(msg)
django.urls.exceptions.NoReverseMatch: Reverse for 'cars/index.html' not found. 'cars/index.html' is not a valid view function or pattern name.
[19Mar 10:52:04] INFO [news.views:16] NewsList.get_queryset called
[19Mar 12:53:19] WARNING [django.request:228] Not Found: /cars/
[19Mar 12:53:29] ERROR [django.request:228] Internal Server Error: /
Traceback (most recent call last):
  File "/home/kotbegemot/Документы/d10/venv/lib/python3.6/site-packages/django/core/handlers/exception.py", line 34, in inner
    response = get_response(request)
  File "/home/kotbegemot/Документы/d10/venv/lib/python3.6/site-packages/django/core/handlers/base.py", line 115, in _get_response
    response = self.process_exception_by_middleware(e, request)
  File "/home/kotbegemot/Документы/d10/venv/lib/python3.6/site-packages/django/core/handlers/base.py", line 113, in _get_response
    response = wrapped_callback(request, *callback_args, **callback_kwargs)
  File "/home/kotbegemot/Документы/d10/deb_test/cars/views.py", line 19, in car_list
    form = CarForm()
NameError: name 'CarForm' is not defined
[19Mar 13:02:16] WARNING [django.security.csrf:228] Forbidden (CSRF token missing or incorrect.): /admin/login/
[19Mar 13:04:35] ERROR [django.request:228] Internal Server Error: /admin/cars/car/
Traceback (most recent call last):
  File "/home/kotbegemot/Документы/d10/venv/lib/python3.6/site-packages/django/db/models/options.py", line 581, in get_field
    return self.fields_map[field_name]
KeyError: '__str__'

During handling of the above exception, another exception occurred:

Traceback (most recent call last):
  File "/home/kotbegemot/Документы/d10/venv/lib/python3.6/site-packages/django/contrib/admin/utils.py", line 262, in lookup_field
    f = _get_non_gfk_field(opts, name)
  File "/home/kotbegemot/Документы/d10/venv/lib/python3.6/site-packages/django/contrib/admin/utils.py", line 293, in _get_non_gfk_field
    field = opts.get_field(name)
  File "/home/kotbegemot/Документы/d10/venv/lib/python3.6/site-packages/django/db/models/options.py", line 583, in get_field
    raise FieldDoesNotExist("%s has no field named '%s'" % (self.object_name, field_name))
django.core.exceptions.FieldDoesNotExist: Car has no field named '__str__'

During handling of the above exception, another exception occurred:

Traceback (most recent call last):
  File "/home/kotbegemot/Документы/d10/venv/lib/python3.6/site-packages/django/core/handlers/exception.py", line 34, in inner
    response = get_response(request)
  File "/home/kotbegemot/Документы/d10/venv/lib/python3.6/site-packages/django/core/handlers/base.py", line 145, in _get_response
    response = self.process_exception_by_middleware(e, request)
  File "/home/kotbegemot/Документы/d10/venv/lib/python3.6/site-packages/django/core/handlers/base.py", line 143, in _get_response
    response = response.render()
  File "/home/kotbegemot/Документы/d10/venv/lib/python3.6/site-packages/django/template/response.py", line 105, in render
    self.content = self.rendered_content
  File "/home/kotbegemot/Документы/d10/venv/lib/python3.6/site-packages/django/template/response.py", line 83, in rendered_content
    return template.render(context, self._request)
  File "/home/kotbegemot/Документы/d10/venv/lib/python3.6/site-packages/django/template/backends/django.py", line 61, in render
    return self.template.render(context)
  File "/home/kotbegemot/Документы/d10/venv/lib/python3.6/site-packages/django/template/base.py", line 171, in render
    return self._render(context)
  File "/home/kotbegemot/Документы/d10/venv/lib/python3.6/site-packages/django/test/utils.py", line 95, in instrumented_test_render
    return self.nodelist.render(context)
  File "/home/kotbegemot/Документы/d10/venv/lib/python3.6/site-packages/django/template/base.py", line 936, in render
    bit = node.render_annotated(context)
  File "/home/kotbegemot/Документы/d10/venv/lib/python3.6/site-packages/django/template/base.py", line 903, in render_annotated
    return self.render(context)
  File "/home/kotbegemot/Документы/d10/venv/lib/python3.6/site-packages/django/template/loader_tags.py", line 150, in render
    return compiled_parent._render(context)
  File "/home/kotbegemot/Документы/d10/venv/lib/python3.6/site-packages/django/test/utils.py", line 95, in instrumented_test_render
    return self.nodelist.render(context)
  File "/home/kotbegemot/Документы/d10/venv/lib/python3.6/site-packages/django/template/base.py", line 936, in render
    bit = node.render_annotated(context)
  File "/home/kotbegemot/Документы/d10/venv/lib/python3.6/site-packages/django/template/base.py", line 903, in render_annotated
    return self.render(context)
  File "/home/kotbegemot/Документы/d10/venv/lib/python3.6/site-packages/django/template/loader_tags.py", line 150, in render
    return compiled_parent._render(context)
  File "/home/kotbegemot/Документы/d10/venv/lib/python3.6/site-packages/django/test/utils.py", line 95, in instrumented_test_render
    return self.nodelist.render(context)
  File "/home/kotbegemot/Документы/d10/venv/lib/python3.6/site-packages/django/template/base.py", line 936, in render
    bit = node.render_annotated(context)
  File "/home/kotbegemot/Документы/d10/venv/lib/python3.6/site-packages/django/template/base.py", line 903, in render_annotated
    return self.render(context)
  File "/home/kotbegemot/Документы/d10/venv/lib/python3.6/site-packages/django/template/loader_tags.py", line 62, in render
    result = block.nodelist.render(context)
  File "/home/kotbegemot/Документы/d10/venv/lib/python3.6/site-packages/django/template/base.py", line 936, in render
    bit = node.render_annotated(context)
  File "/home/kotbegemot/Документы/d10/venv/lib/python3.6/site-packages/django/template/base.py", line 903, in render_annotated
    return self.render(context)
  File "/home/kotbegemot/Документы/d10/venv/lib/python3.6/site-packages/django/template/loader_tags.py", line 62, in render
    result = block.nodelist.render(context)
  File "/home/kotbegemot/Документы/d10/venv/lib/python3.6/site-packages/django/template/base.py", line 936, in render
    bit = node.render_annotated(context)
  File "/home/kotbegemot/Документы/d10/venv/lib/python3.6/site-packages/django/template/base.py", line 903, in render_annotated
    return self.render(context)
  File "/home/kotbegemot/Документы/d10/venv/lib/python3.6/site-packages/django/contrib/admin/templatetags/base.py", line 33, in render
    return super().render(context)
  File "/home/kotbegemot/Документы/d10/venv/lib/python3.6/site-packages/django/template/library.py", line 214, in render
    _dict = self.func(*resolved_args, **resolved_kwargs)
  File "/home/kotbegemot/Документы/d10/venv/lib/python3.6/site-packages/django/contrib/admin/templatetags/admin_list.py", line 342, in result_list
    'results': list(results(cl)),
  File "/home/kotbegemot/Документы/d10/venv/lib/python3.6/site-packages/django/contrib/admin/templatetags/admin_list.py", line 318, in results
    yield ResultList(None, items_for_result(cl, res, None))
  File "/home/kotbegemot/Документы/d10/venv/lib/python3.6/site-packages/django/contrib/admin/templatetags/admin_list.py", line 309, in __init__
    super().__init__(*items)
  File "/home/kotbegemot/Документы/d10/venv/lib/python3.6/site-packages/django/contrib/admin/templatetags/admin_list.py", line 232, in items_for_result
    f, attr, value = lookup_field(field_name, result, cl.model_admin)
  File "/home/kotbegemot/Документы/d10/venv/lib/python3.6/site-packages/django/contrib/admin/utils.py", line 275, in lookup_field
    value = attr()
  File "/home/kotbegemot/Документы/d10/deb_test/cars/models.py", line 18, in __str__
    return {}, {}.format(self.manufacturer, self.model)
AttributeError: 'dict' object has no attribute 'format'
[19Mar 13:09:54] ERROR [django.request:228] Internal Server Error: /
Traceback (most recent call last):
  File "/home/kotbegemot/Документы/d10/venv/lib/python3.6/site-packages/django/core/handlers/exception.py", line 34, in inner
    response = get_response(request)
  File "/home/kotbegemot/Документы/d10/venv/lib/python3.6/site-packages/django/core/handlers/base.py", line 115, in _get_response
    response = self.process_exception_by_middleware(e, request)
  File "/home/kotbegemot/Документы/d10/venv/lib/python3.6/site-packages/django/core/handlers/base.py", line 113, in _get_response
    response = wrapped_callback(request, *callback_args, **callback_kwargs)
  File "/home/kotbegemot/Документы/d10/deb_test/cars/views.py", line 30, in car_list
    Q(colour__icontains=request.GET.get('colour'))
  File "/home/kotbegemot/Документы/d10/venv/lib/python3.6/site-packages/django/db/models/manager.py", line 82, in manager_method
    return getattr(self.get_queryset(), name)(*args, **kwargs)
  File "/home/kotbegemot/Документы/d10/venv/lib/python3.6/site-packages/django/db/models/query.py", line 904, in filter
    return self._filter_or_exclude(False, *args, **kwargs)
  File "/home/kotbegemot/Документы/d10/venv/lib/python3.6/site-packages/django/db/models/query.py", line 923, in _filter_or_exclude
    clone.query.add_q(Q(*args, **kwargs))
  File "/home/kotbegemot/Документы/d10/venv/lib/python3.6/site-packages/django/db/models/sql/query.py", line 1350, in add_q
    clause, _ = self._add_q(q_object, self.used_aliases)
  File "/home/kotbegemot/Документы/d10/venv/lib/python3.6/site-packages/django/db/models/sql/query.py", line 1373, in _add_q
    check_filterable,
  File "/home/kotbegemot/Документы/d10/venv/lib/python3.6/site-packages/django/db/models/sql/query.py", line 1381, in _add_q
    check_filterable=check_filterable,
  File "/home/kotbegemot/Документы/d10/venv/lib/python3.6/site-packages/django/db/models/sql/query.py", line 1250, in build_filter
    lookups, parts, reffed_expression = self.solve_lookup_type(arg)
  File "/home/kotbegemot/Документы/d10/venv/lib/python3.6/site-packages/django/db/models/sql/query.py", line 1087, in solve_lookup_type
    _, field, _, lookup_parts = self.names_to_path(lookup_splitted, self.get_meta())
  File "/home/kotbegemot/Документы/d10/venv/lib/python3.6/site-packages/django/db/models/sql/query.py", line 1483, in names_to_path
    "Choices are: %s" % (name, ", ".join(available)))
django.core.exceptions.FieldError: Cannot resolve keyword 'model_of_auto' into field. Choices are: color, id, manufacturer, model, transmission, year_of_issue
[19Mar 13:10:44] ERROR [django.request:228] Internal Server Error: /
Traceback (most recent call last):
  File "/home/kotbegemot/Документы/d10/venv/lib/python3.6/site-packages/django/core/handlers/exception.py", line 34, in inner
    response = get_response(request)
  File "/home/kotbegemot/Документы/d10/venv/lib/python3.6/site-packages/django/core/handlers/base.py", line 115, in _get_response
    response = self.process_exception_by_middleware(e, request)
  File "/home/kotbegemot/Документы/d10/venv/lib/python3.6/site-packages/django/core/handlers/base.py", line 113, in _get_response
    response = wrapped_callback(request, *callback_args, **callback_kwargs)
  File "/home/kotbegemot/Документы/d10/deb_test/cars/views.py", line 30, in car_list
    Q(colour__icontains=request.GET.get('colour'))
  File "/home/kotbegemot/Документы/d10/venv/lib/python3.6/site-packages/django/db/models/manager.py", line 82, in manager_method
    return getattr(self.get_queryset(), name)(*args, **kwargs)
  File "/home/kotbegemot/Документы/d10/venv/lib/python3.6/site-packages/django/db/models/query.py", line 904, in filter
    return self._filter_or_exclude(False, *args, **kwargs)
  File "/home/kotbegemot/Документы/d10/venv/lib/python3.6/site-packages/django/db/models/query.py", line 923, in _filter_or_exclude
    clone.query.add_q(Q(*args, **kwargs))
  File "/home/kotbegemot/Документы/d10/venv/lib/python3.6/site-packages/django/db/models/sql/query.py", line 1350, in add_q
    clause, _ = self._add_q(q_object, self.used_aliases)
  File "/home/kotbegemot/Документы/d10/venv/lib/python3.6/site-packages/django/db/models/sql/query.py", line 1373, in _add_q
    check_filterable,
  File "/home/kotbegemot/Документы/d10/venv/lib/python3.6/site-packages/django/db/models/sql/query.py", line 1381, in _add_q
    check_filterable=check_filterable,
  File "/home/kotbegemot/Документы/d10/venv/lib/python3.6/site-packages/django/db/models/sql/query.py", line 1250, in build_filter
    lookups, parts, reffed_expression = self.solve_lookup_type(arg)
  File "/home/kotbegemot/Документы/d10/venv/lib/python3.6/site-packages/django/db/models/sql/query.py", line 1087, in solve_lookup_type
    _, field, _, lookup_parts = self.names_to_path(lookup_splitted, self.get_meta())
  File "/home/kotbegemot/Документы/d10/venv/lib/python3.6/site-packages/django/db/models/sql/query.py", line 1483, in names_to_path
    "Choices are: %s" % (name, ", ".join(available)))
django.core.exceptions.FieldError: Cannot resolve keyword 'model_of_auto' into field. Choices are: color, id, manufacturer, model, transmission, year_of_issue
[19Mar 13:11:04] ERROR [django.request:228] Internal Server Error: /
Traceback (most recent call last):
  File "/home/kotbegemot/Документы/d10/venv/lib/python3.6/site-packages/django/core/handlers/exception.py", line 34, in inner
    response = get_response(request)
  File "/home/kotbegemot/Документы/d10/venv/lib/python3.6/site-packages/django/core/handlers/base.py", line 115, in _get_response
    response = self.process_exception_by_middleware(e, request)
  File "/home/kotbegemot/Документы/d10/venv/lib/python3.6/site-packages/django/core/handlers/base.py", line 113, in _get_response
    response = wrapped_callback(request, *callback_args, **callback_kwargs)
  File "/home/kotbegemot/Документы/d10/deb_test/cars/views.py", line 30, in car_list
    Q(colour__icontains=request.GET.get('color'))
  File "/home/kotbegemot/Документы/d10/venv/lib/python3.6/site-packages/django/db/models/manager.py", line 82, in manager_method
    return getattr(self.get_queryset(), name)(*args, **kwargs)
  File "/home/kotbegemot/Документы/d10/venv/lib/python3.6/site-packages/django/db/models/query.py", line 904, in filter
    return self._filter_or_exclude(False, *args, **kwargs)
  File "/home/kotbegemot/Документы/d10/venv/lib/python3.6/site-packages/django/db/models/query.py", line 923, in _filter_or_exclude
    clone.query.add_q(Q(*args, **kwargs))
  File "/home/kotbegemot/Документы/d10/venv/lib/python3.6/site-packages/django/db/models/sql/query.py", line 1350, in add_q
    clause, _ = self._add_q(q_object, self.used_aliases)
  File "/home/kotbegemot/Документы/d10/venv/lib/python3.6/site-packages/django/db/models/sql/query.py", line 1373, in _add_q
    check_filterable,
  File "/home/kotbegemot/Документы/d10/venv/lib/python3.6/site-packages/django/db/models/sql/query.py", line 1381, in _add_q
    check_filterable=check_filterable,
  File "/home/kotbegemot/Документы/d10/venv/lib/python3.6/site-packages/django/db/models/sql/query.py", line 1250, in build_filter
    lookups, parts, reffed_expression = self.solve_lookup_type(arg)
  File "/home/kotbegemot/Документы/d10/venv/lib/python3.6/site-packages/django/db/models/sql/query.py", line 1087, in solve_lookup_type
    _, field, _, lookup_parts = self.names_to_path(lookup_splitted, self.get_meta())
  File "/home/kotbegemot/Документы/d10/venv/lib/python3.6/site-packages/django/db/models/sql/query.py", line 1483, in names_to_path
    "Choices are: %s" % (name, ", ".join(available)))
django.core.exceptions.FieldError: Cannot resolve keyword 'model_of_auto' into field. Choices are: color, id, manufacturer, model, transmission, year_of_issue
[19Mar 13:12:33] ERROR [django.request:228] Internal Server Error: /
Traceback (most recent call last):
  File "/home/kotbegemot/Документы/d10/venv/lib/python3.6/site-packages/django/core/handlers/exception.py", line 34, in inner
    response = get_response(request)
  File "/home/kotbegemot/Документы/d10/venv/lib/python3.6/site-packages/django/core/handlers/base.py", line 115, in _get_response
    response = self.process_exception_by_middleware(e, request)
  File "/home/kotbegemot/Документы/d10/venv/lib/python3.6/site-packages/django/core/handlers/base.py", line 113, in _get_response
    response = wrapped_callback(request, *callback_args, **callback_kwargs)
  File "/home/kotbegemot/Документы/d10/deb_test/cars/views.py", line 30, in car_list
    Q(colour__icontains=request.GET.get('colour'))
  File "/home/kotbegemot/Документы/d10/venv/lib/python3.6/site-packages/django/db/models/manager.py", line 82, in manager_method
    return getattr(self.get_queryset(), name)(*args, **kwargs)
  File "/home/kotbegemot/Документы/d10/venv/lib/python3.6/site-packages/django/db/models/query.py", line 904, in filter
    return self._filter_or_exclude(False, *args, **kwargs)
  File "/home/kotbegemot/Документы/d10/venv/lib/python3.6/site-packages/django/db/models/query.py", line 923, in _filter_or_exclude
    clone.query.add_q(Q(*args, **kwargs))
  File "/home/kotbegemot/Документы/d10/venv/lib/python3.6/site-packages/django/db/models/sql/query.py", line 1350, in add_q
    clause, _ = self._add_q(q_object, self.used_aliases)
  File "/home/kotbegemot/Документы/d10/venv/lib/python3.6/site-packages/django/db/models/sql/query.py", line 1373, in _add_q
    check_filterable,
  File "/home/kotbegemot/Документы/d10/venv/lib/python3.6/site-packages/django/db/models/sql/query.py", line 1381, in _add_q
    check_filterable=check_filterable,
  File "/home/kotbegemot/Документы/d10/venv/lib/python3.6/site-packages/django/db/models/sql/query.py", line 1250, in build_filter
    lookups, parts, reffed_expression = self.solve_lookup_type(arg)
  File "/home/kotbegemot/Документы/d10/venv/lib/python3.6/site-packages/django/db/models/sql/query.py", line 1087, in solve_lookup_type
    _, field, _, lookup_parts = self.names_to_path(lookup_splitted, self.get_meta())
  File "/home/kotbegemot/Документы/d10/venv/lib/python3.6/site-packages/django/db/models/sql/query.py", line 1483, in names_to_path
    "Choices are: %s" % (name, ", ".join(available)))
django.core.exceptions.FieldError: Cannot resolve keyword 'model_of_auto' into field. Choices are: colour, id, manufacturer, model, transmission, year_of_issue
[19Mar 13:13:06] ERROR [django.request:228] Internal Server Error: /
Traceback (most recent call last):
  File "/home/kotbegemot/Документы/d10/venv/lib/python3.6/site-packages/django/core/handlers/exception.py", line 34, in inner
    response = get_response(request)
  File "/home/kotbegemot/Документы/d10/venv/lib/python3.6/site-packages/django/core/handlers/base.py", line 115, in _get_response
    response = self.process_exception_by_middleware(e, request)
  File "/home/kotbegemot/Документы/d10/venv/lib/python3.6/site-packages/django/core/handlers/base.py", line 113, in _get_response
    response = wrapped_callback(request, *callback_args, **callback_kwargs)
  File "/home/kotbegemot/Документы/d10/deb_test/cars/views.py", line 30, in car_list
    Q(colour__icontains=request.GET.get('colour'))
  File "/home/kotbegemot/Документы/d10/venv/lib/python3.6/site-packages/django/db/models/manager.py", line 82, in manager_method
    return getattr(self.get_queryset(), name)(*args, **kwargs)
  File "/home/kotbegemot/Документы/d10/venv/lib/python3.6/site-packages/django/db/models/query.py", line 904, in filter
    return self._filter_or_exclude(False, *args, **kwargs)
  File "/home/kotbegemot/Документы/d10/venv/lib/python3.6/site-packages/django/db/models/query.py", line 923, in _filter_or_exclude
    clone.query.add_q(Q(*args, **kwargs))
  File "/home/kotbegemot/Документы/d10/venv/lib/python3.6/site-packages/django/db/models/sql/query.py", line 1350, in add_q
    clause, _ = self._add_q(q_object, self.used_aliases)
  File "/home/kotbegemot/Документы/d10/venv/lib/python3.6/site-packages/django/db/models/sql/query.py", line 1373, in _add_q
    check_filterable,
  File "/home/kotbegemot/Документы/d10/venv/lib/python3.6/site-packages/django/db/models/sql/query.py", line 1381, in _add_q
    check_filterable=check_filterable,
  File "/home/kotbegemot/Документы/d10/venv/lib/python3.6/site-packages/django/db/models/sql/query.py", line 1311, in build_filter
    condition = self.build_lookup(lookups, col, value)
  File "/home/kotbegemot/Документы/d10/venv/lib/python3.6/site-packages/django/db/models/sql/query.py", line 1170, in build_lookup
    raise ValueError("Cannot use None as a query value")
ValueError: Cannot use None as a query value
[19Mar 14:03:08] ERROR [django.request:228] Internal Server Error: /test/
Traceback (most recent call last):
  File "/home/kotbegemot/Документы/d10/venv/lib/python3.6/site-packages/django/core/handlers/exception.py", line 34, in inner
    response = get_response(request)
  File "/home/kotbegemot/Документы/d10/venv/lib/python3.6/site-packages/django/core/handlers/base.py", line 115, in _get_response
    response = self.process_exception_by_middleware(e, request)
  File "/home/kotbegemot/Документы/d10/venv/lib/python3.6/site-packages/django/core/handlers/base.py", line 113, in _get_response
    response = wrapped_callback(request, *callback_args, **callback_kwargs)
  File "/home/kotbegemot/Документы/d10/venv/lib/python3.6/site-packages/django/views/generic/base.py", line 71, in view
    return self.dispatch(request, *args, **kwargs)
  File "/home/kotbegemot/Документы/d10/venv/lib/python3.6/site-packages/django/views/generic/base.py", line 97, in dispatch
    return handler(request, *args, **kwargs)
TypeError: get() takes 1 positional argument but 2 were given
[19Mar 14:03:42] ERROR [django.request:228] Internal Server Error: /test/
Traceback (most recent call last):
  File "/home/kotbegemot/Документы/d10/venv/lib/python3.6/site-packages/django/core/handlers/exception.py", line 34, in inner
    response = get_response(request)
  File "/home/kotbegemot/Документы/d10/venv/lib/python3.6/site-packages/django/core/handlers/base.py", line 115, in _get_response
    response = self.process_exception_by_middleware(e, request)
  File "/home/kotbegemot/Документы/d10/venv/lib/python3.6/site-packages/django/core/handlers/base.py", line 113, in _get_response
    response = wrapped_callback(request, *callback_args, **callback_kwargs)
  File "/home/kotbegemot/Документы/d10/venv/lib/python3.6/site-packages/django/views/generic/base.py", line 71, in view
    return self.dispatch(request, *args, **kwargs)
  File "/home/kotbegemot/Документы/d10/venv/lib/python3.6/site-packages/django/views/generic/base.py", line 97, in dispatch
    return handler(request, *args, **kwargs)
  File "/home/kotbegemot/Документы/d10/deb_test/cars/views.py", line 37, in get
    if request.Get:
AttributeError: 'WSGIRequest' object has no attribute 'Get'
[19Mar 14:04:26] ERROR [django.request:228] Internal Server Error: /test/
Traceback (most recent call last):
  File "/home/kotbegemot/Документы/d10/venv/lib/python3.6/site-packages/django/core/handlers/exception.py", line 34, in inner
    response = get_response(request)
  File "/home/kotbegemot/Документы/d10/venv/lib/python3.6/site-packages/django/core/handlers/base.py", line 115, in _get_response
    response = self.process_exception_by_middleware(e, request)
  File "/home/kotbegemot/Документы/d10/venv/lib/python3.6/site-packages/django/core/handlers/base.py", line 113, in _get_response
    response = wrapped_callback(request, *callback_args, **callback_kwargs)
  File "/home/kotbegemot/Документы/d10/venv/lib/python3.6/site-packages/django/views/generic/base.py", line 71, in view
    return self.dispatch(request, *args, **kwargs)
  File "/home/kotbegemot/Документы/d10/venv/lib/python3.6/site-packages/django/views/generic/base.py", line 97, in dispatch
    return handler(request, *args, **kwargs)
  File "/home/kotbegemot/Документы/d10/deb_test/cars/views.py", line 37, in get
    if request.Get:
AttributeError: 'WSGIRequest' object has no attribute 'Get'
[19Mar 14:06:15] ERROR [django.request:228] Internal Server Error: /test/
Traceback (most recent call last):
  File "/home/kotbegemot/Документы/d10/venv/lib/python3.6/site-packages/django/core/handlers/exception.py", line 34, in inner
    response = get_response(request)
  File "/home/kotbegemot/Документы/d10/venv/lib/python3.6/site-packages/django/core/handlers/base.py", line 115, in _get_response
    response = self.process_exception_by_middleware(e, request)
  File "/home/kotbegemot/Документы/d10/venv/lib/python3.6/site-packages/django/core/handlers/base.py", line 113, in _get_response
    response = wrapped_callback(request, *callback_args, **callback_kwargs)
  File "/home/kotbegemot/Документы/d10/venv/lib/python3.6/site-packages/django/views/generic/base.py", line 71, in view
    return self.dispatch(request, *args, **kwargs)
  File "/home/kotbegemot/Документы/d10/venv/lib/python3.6/site-packages/django/views/generic/base.py", line 97, in dispatch
    return handler(request, *args, **kwargs)
  File "/home/kotbegemot/Документы/d10/deb_test/cars/views.py", line 37, in get
    if request.Get:
AttributeError: 'WSGIRequest' object has no attribute 'Get'
[19Mar 14:23:50] ERROR [django.request:228] Internal Server Error: /test/
Traceback (most recent call last):
  File "/home/kotbegemot/Документы/d10/venv/lib/python3.6/site-packages/django/core/handlers/exception.py", line 34, in inner
    response = get_response(request)
  File "/home/kotbegemot/Документы/d10/venv/lib/python3.6/site-packages/django/core/handlers/base.py", line 115, in _get_response
    response = self.process_exception_by_middleware(e, request)
  File "/home/kotbegemot/Документы/d10/venv/lib/python3.6/site-packages/django/core/handlers/base.py", line 113, in _get_response
    response = wrapped_callback(request, *callback_args, **callback_kwargs)
  File "/home/kotbegemot/Документы/d10/venv/lib/python3.6/site-packages/django/views/generic/base.py", line 71, in view
    return self.dispatch(request, *args, **kwargs)
  File "/home/kotbegemot/Документы/d10/venv/lib/python3.6/site-packages/django/views/generic/base.py", line 97, in dispatch
    return handler(request, *args, **kwargs)
  File "/home/kotbegemot/Документы/d10/deb_test/cars/views.py", line 46, in get
    return render(request, 'cars/cars_list.html', {'form': form, 'cars': cars})
  File "/home/kotbegemot/Документы/d10/venv/lib/python3.6/site-packages/django/shortcuts.py", line 19, in render
    content = loader.render_to_string(template_name, context, request, using=using)
  File "/home/kotbegemot/Документы/d10/venv/lib/python3.6/site-packages/django/template/loader.py", line 61, in render_to_string
    template = get_template(template_name, using=using)
  File "/home/kotbegemot/Документы/d10/venv/lib/python3.6/site-packages/django/template/loader.py", line 15, in get_template
    return engine.get_template(template_name)
  File "/home/kotbegemot/Документы/d10/venv/lib/python3.6/site-packages/django/template/backends/django.py", line 34, in get_template
    return Template(self.engine.get_template(template_name), self)
  File "/home/kotbegemot/Документы/d10/venv/lib/python3.6/site-packages/django/template/engine.py", line 143, in get_template
    template, origin = self.find_template(template_name)
  File "/home/kotbegemot/Документы/d10/venv/lib/python3.6/site-packages/django/template/engine.py", line 125, in find_template
    template = loader.get_template(name, skip=skip)
  File "/home/kotbegemot/Документы/d10/venv/lib/python3.6/site-packages/django/template/loaders/base.py", line 30, in get_template
    contents, origin, origin.template_name, self.engine,
  File "/home/kotbegemot/Документы/d10/venv/lib/python3.6/site-packages/django/template/base.py", line 156, in __init__
    self.nodelist = self.compile_nodelist()
  File "/home/kotbegemot/Документы/d10/venv/lib/python3.6/site-packages/django/template/base.py", line 194, in compile_nodelist
    return parser.parse()
  File "/home/kotbegemot/Документы/d10/venv/lib/python3.6/site-packages/django/template/base.py", line 448, in parse
    raise self.error(token, e)
  File "/home/kotbegemot/Документы/d10/venv/lib/python3.6/site-packages/django/template/base.py", line 446, in parse
    filter_expression = self.compile_filter(token.contents)
  File "/home/kotbegemot/Документы/d10/venv/lib/python3.6/site-packages/django/template/base.py", line 562, in compile_filter
    return FilterExpression(token, self)
  File "/home/kotbegemot/Документы/d10/venv/lib/python3.6/site-packages/django/template/base.py", line 662, in __init__
    "from '%s'" % (token[upto:], token))
django.template.exceptions.TemplateSyntaxError: Could not parse the remainder: ' 'cars_list_url'' from 'url 'cars_list_url''
[19Mar 15:13:21] WARNING [django.request:228] Not Found: /test&colour=black
[19Mar 16:13:11] ERROR [django.request:228] Internal Server Error: /
Traceback (most recent call last):
  File "/home/kotbegemot/Документы/d10/venv/lib/python3.6/site-packages/django/core/handlers/exception.py", line 34, in inner
    response = get_response(request)
  File "/home/kotbegemot/Документы/d10/venv/lib/python3.6/site-packages/django/core/handlers/base.py", line 115, in _get_response
    response = self.process_exception_by_middleware(e, request)
  File "/home/kotbegemot/Документы/d10/venv/lib/python3.6/site-packages/django/core/handlers/base.py", line 113, in _get_response
    response = wrapped_callback(request, *callback_args, **callback_kwargs)
  File "/home/kotbegemot/Документы/d10/venv/lib/python3.6/site-packages/django/views/generic/base.py", line 71, in view
    return self.dispatch(request, *args, **kwargs)
  File "/home/kotbegemot/Документы/d10/venv/lib/python3.6/site-packages/django/views/generic/base.py", line 97, in dispatch
    return handler(request, *args, **kwargs)
  File "/home/kotbegemot/Документы/d10/deb_test/cars/views.py", line 11, in get
    form = CarForm(request.GET)
  File "/home/kotbegemot/Документы/d10/venv/lib/python3.6/site-packages/django/forms/models.py", line 286, in __init__
    raise ValueError('ModelForm has no model class specified.')
ValueError: ModelForm has no model class specified.
[19Mar 16:15:48] ERROR [django.request:228] Internal Server Error: /
Traceback (most recent call last):
  File "/home/kotbegemot/Документы/d10/venv/lib/python3.6/site-packages/django/core/handlers/exception.py", line 34, in inner
    response = get_response(request)
  File "/home/kotbegemot/Документы/d10/venv/lib/python3.6/site-packages/django/core/handlers/base.py", line 115, in _get_response
    response = self.process_exception_by_middleware(e, request)
  File "/home/kotbegemot/Документы/d10/venv/lib/python3.6/site-packages/django/core/handlers/base.py", line 113, in _get_response
    response = wrapped_callback(request, *callback_args, **callback_kwargs)
  File "/home/kotbegemot/Документы/d10/venv/lib/python3.6/site-packages/django/views/generic/base.py", line 71, in view
    return self.dispatch(request, *args, **kwargs)
  File "/home/kotbegemot/Документы/d10/venv/lib/python3.6/site-packages/django/views/generic/base.py", line 97, in dispatch
    return handler(request, *args, **kwargs)
  File "/home/kotbegemot/Документы/d10/deb_test/cars/views.py", line 11, in get
    form = CarForm(request.GET)
  File "/home/kotbegemot/Документы/d10/venv/lib/python3.6/site-packages/django/forms/models.py", line 286, in __init__
    raise ValueError('ModelForm has no model class specified.')
ValueError: ModelForm has no model class specified.
[19Mar 16:15:56] ERROR [django.request:228] Internal Server Error: /
Traceback (most recent call last):
  File "/home/kotbegemot/Документы/d10/venv/lib/python3.6/site-packages/django/core/handlers/exception.py", line 34, in inner
    response = get_response(request)
  File "/home/kotbegemot/Документы/d10/venv/lib/python3.6/site-packages/django/core/handlers/base.py", line 115, in _get_response
    response = self.process_exception_by_middleware(e, request)
  File "/home/kotbegemot/Документы/d10/venv/lib/python3.6/site-packages/django/core/handlers/base.py", line 113, in _get_response
    response = wrapped_callback(request, *callback_args, **callback_kwargs)
  File "/home/kotbegemot/Документы/d10/venv/lib/python3.6/site-packages/django/views/generic/base.py", line 71, in view
    return self.dispatch(request, *args, **kwargs)
  File "/home/kotbegemot/Документы/d10/venv/lib/python3.6/site-packages/django/views/generic/base.py", line 97, in dispatch
    return handler(request, *args, **kwargs)
  File "/home/kotbegemot/Документы/d10/deb_test/cars/views.py", line 19, in get
    form = CarForm()
  File "/home/kotbegemot/Документы/d10/venv/lib/python3.6/site-packages/django/forms/models.py", line 286, in __init__
    raise ValueError('ModelForm has no model class specified.')
ValueError: ModelForm has no model class specified.
